Workbook

Sheet Worklog_Tasks&Times
A1: Date | B1: Status | C1: Task | D1: Description/Planning | E1: Task Type | F1: Most suited ILO | G1: Est Hours | H1: Actual Hours | I1: Diff | J1: Evidence link | K1: Task reflection / notes
A2: Week 1
A3: week plan: | B3: Set up repo, environment and tooling. Read core literature. Make early architecture and risk-scoring decisions. Finalise H1-H4 and plan project structure.
A4: Known Risks | B4: Environment/GPU setup may take longer than planned.
A5: 46125 | B5: Done | C5: Create repo and init structure | D5: GitHub repo, folder layout | E5: Programming | F5: Product Quality | G5: 2 | H5: 2 | I5: =H5-G5 -> 0 | J5: repo root
A6: 46125 | B6: Done | C6: Set up Python/CUDA environment | D6: PyTorch, Ultralytics, torchvision install | E6: Programming | F6: Product Quality | G6: 3 | H6: 3 | I6: =H6-G6 -> 0 | J6: requirements.txt
A7: 46126 | B7: Done | C7: Read YOLO/Faster R-CNN/RDD2022/CRDDC papers | D7: Core architecture and benchmark papers | E7: Study | F7: Research Relevance | G7: 3 | H7: 3.5 | I7: =H7-G7 -> 0.5 | J7: references.bib
A8: 46127 | B8: Done | C8: Read OSMnx/routing/PCI literature | D8: Routing and risk-scoring background | E8: Study | F8: Research Relevance | G8: 3 | H8: 3 | I8: =H8-G8 -> 0 | J8: references.bib
A9: 46128 | B9: Done | C9: Decide YOLOv8n vs Faster R-CNN as the two architectures | D9: One-stage vs two-stage comparison | E9: Design | F9: Research Methodology | G9: 1.5 | H9: 1.5 | I9: =H9-G9 -> 0 | J9: thesis 3.2
A10: 46128 | B10: Done | C10: Decide on rule-based (not learned) risk scoring | D10: Auditability over accuracy | E10: Design | F10: Research Methodology | G10: 1 | H10: 1 | I10: =H10-G10 -> 0 | J10: thesis 3.2
A11: 46128 | B11: Done | C11: Supervisor kickoff check-in | D11: Review architecture/risk-scoring decisions and H1-H4 wording | E11: Planning | F11: Learning - Feedback | G11: 0.5 | H11: 0.5 | I11: =H11-G11 -> 0
A12: 46129 | B12: Done | C12: Finalise H1-H4 wording | D12: From proposal feedback | E12: Design | F12: Research Methodology | G12: 2 | H12: 2 | I12: =H12-G12 -> 0
A13: 46129 | B13: Done | C13: Plan src/ structure and config approach | D13: Folder conventions, config pattern | E13: Planning | F13: Project Management - Process | G13: 2 | H13: 2 | I13: =H13-G13 -> 0
E14: Total Hours | G14: =SUM(G5:G13) -> 18 | H14: =SUM(H5:H13) -> 18.5 | I14: =H14-G14 -> 0.5
A15: Week 2
A16: week plan: | B16: Explore RDD2022. Decide which classes to keep. Build the small validation dataset. Plan the app page structure.
A17: Known Risks | B17: RDD2022 download and class filtering may surface format issues.
A18: 46132 | B18: Done | C18: Download RDD2022, verify folders/counts | D18: 7 country sources | E18: Research | F18: Research Methodology | G18: 3 | H18: 3 | I18: =H18-G18 -> 0 | J18: data
A19: 46132 | B19: Done | C19: Explore class/country distribution in notebook | D19: First look at the raw pool | E19: Research | F19: Research Methodology | G19: 3 | H19: 3 | I19: =H19-G19 -> 0 | J19: visual dataset inspection notebook
A20: 46133 | B20: Done | C20: Decide to keep 4 damage classes, filter 5th | D20: D00/D10/D20/D40 only | E20: Design | F20: Research Methodology | G20: 3 | H20: 3 | I20: =H20-G20 -> 0 | J20: scripts/
A21: 46133 | B21: Done | C21: Write annotation conversion script | D21: Convert raw RDD2022 labels | E21: Programming | F21: Product Quality | G21: 3 | H21: 3 | I21: =H21-G21 -> 0 | J21: scripts/
A22: 46135 | B22: Done | C22: Build small dataset split (277/60/60) | D22: First dataset scale, for pipeline validation | E22: Programming | F22: Research Methodology | G22: 3 | H22: 3 | I22: =H22-G22 -> 0 | J22: data
A23: 46135 | B23: Done | C23: Verify small dataset integrity | D23: File counts, label format | E23: Testing | F23: Product Quality | G23: 2 | H23: 2 | I23: =H23-G23 -> 0 | J23: scripts
A24: 46135 | B24: Done | C24: Research CVAT for later manual annotation | D24: Tool choice for the Sofia dataset | E24: Study | F24: Research Relevance | G24: 1.5 | H24: 1.5 | I24: =H24-G24 -> 0
A25: 46136 | B25: Done | C25: Plan Streamlit app page structure | D25: Dashboard/Upload/Map/Route pages | E25: Planning | F25: Project Management - Process | G25: 1.5 | H25: 1.5 | I25: =H25-G25 -> 0
E26: Total Hours | G26: =SUM(G16:G25) -> 20 | H26: =SUM(H16:H25) -> 20 | I26: =H26-G26 -> 0
A27: Week 3
A28: week plan: | B28: Train the first models on the small dataset. Start researching the geospatial and app layers needed for a full pipeline.
A29: Known Risks | B29: Faster R-CNN memory footprint on 8GB GPU is untested.
A30: 46139 | B30: Done | C30: Write YOLOv8n training config | D30: Image size, batch, early stop | E30: Programming | F30: Product Quality | G30: 2 | H30: 2 | I30: =H30-G30 -> 0 | J30: first YOLO training
A31: 46139 | B31: Done | C31: Write Faster R-CNN training config | D31: Grad accumulation, mixed precision | E31: Programming | F31: Product Quality | G31: 3 | H31: 3 | I31: =H31-G31 -> 0 | J31: first YOLO training
A32: 46140 | B32: Done | C32: Debug FRCNN memory errors | D32: 8GB GPU constraint | E32: Debugging | F32: Project Management - Risk | G32: 2 | H32: 2.5 | I32: =H32-G32 -> 0.5 | J32: first FasteRNN training
A33: 46140 | B33: Done | C33: Train YOLOv8n on small dataset | D33: First full run | E33: Programming | F33: Research Methodology | G33: 3 | H33: 3 | I33: =H33-G33 -> 0 | J33: first YOLO training
A34: 46142 | B34: Done | C34: Train Faster R-CNN on small dataset | D34: First full run | E34: Programming | F34: Research Methodology | G34: 4 | H34: 4 | I34: =H34-G34 -> 0 | J34: first FasteRNN training
A35: 46142 | B35: Done | C35: Evaluate both small-dataset models | D35: P/R/F1/mAP | E35: Testing | F35: Research Methodology | G35: 2 | H35: 2 | I35: =H35-G35 -> 0 | J35: outputs/reports/
A36: 46143 | B36: Done | C36: Research OSMnx and Folium basics | D36: For the routing/map layers | E36: Study | F36: Research Relevance | G36: 2 | H36: 2 | I36: =H36-G36 -> 0
A37: 46143 | B37: Done | C37: Draft pipeline architecture diagram | D37: First version of the overview figure | E37: Design | F37: Research Methodology | G37: 2 | H37: 2 | I37: =H37-G37 -> 0 | J37: thesis figure 1
E38: Total Hours | G38: =SUM(G30:G37) -> 20 | H38: =SUM(H30:H37) -> 20.5 | I38: =H38-G38 -> 0.5
A39: Week 4
A40: week plan: | B40: Design and implement the risk-scoring model, so the small-dataset model's output can be scored.
...

Sheet Overview
B2: Learning Objective | C2: W1 | D2: W2 | E2: W3 | F2: W4 | G2: W5 | H2: W6 | I2: W7 | J2: W8 | K2: Total Hours for objective
B3: ='Drop-downs'!C2 -> - | K3: =SUM(C3:J3) -> 0
B4: ='Drop-downs'!C3 -> Research Relevance | C4: =IFERROR(__xludf.DUMMYFUNCTION("IFERROR(SUM(FILTER('Worklog_Tasks&Times'!$H$5:$H$14,'Worklog_Tasks&Times'!$F$5:$F$14=$B4)),0)"),0) -> 0 | K4: =SUM(C4:J4) -> 0
B5: ='Drop-downs'!C4 -> Research Methodology | K5: =SUM(C5:J5) -> 0
B6: ='Drop-downs'!C5 -> Research Application | K6: =SUM(C6:J6) -> 0
B7: ='Drop-downs'!C6 -> Product Usefulness | K7: =SUM(C7:J7) -> 0
B8: ='Drop-downs'!C7 -> Product Quality | K8: =SUM(C8:J8) -> 0
B9: ='Drop-downs'!C8 -> Project Management - Process | K9: =SUM(C9:J9) -> 0
B10: ='Drop-downs'!C9 -> Project Management - Risk | K10: =SUM(C10:J10) -> 0
B11: ='Drop-downs'!C10 -> Professionalism - Collaboration | K11: =SUM(C11:J11) -> 0
B12: TOTAL HOURS PER WEEK | C12: =SUM(C3:C11) -> 0 | D12: =SUM(D3:D11) -> 0 | E12: =SUM(E3:E11) -> 0 | F12: =SUM(F3:F11) -> 0 | G12: =SUM(G3:G11) -> 0 | H12: =SUM(H3:H11) -> 0 | I12: =SUM(I3:I11) -> 0 | J12: =SUM(J3:J11) -> 0
B14: Use this to plan a high level allocation for all 320 hours you are expected to devote to the course during this block. How do you want to allocate your hours for each week? Why 320 hours? The European Higher Education Framework states that an academic credit is expected to require 25-28 hours to earn. You earn 15 credits per block, so you should be expected to devote 375 hours to accomplish that. CMGT students do fewer hours because the program is more intense.
B18: Use a formula like this to get your data from Worklog sheet : =IFERROR(SUM(FILTER('Worklog_Tasks&Times'!$H$5:$H$14,'Worklog_Tasks&Times'!$F$5:$F$14=$B4)),0)

Sheet Drop-downs
A1: Task Status | B1: Task Type | C1: ILO selection
A2: - | B2: - | C2: -
A3: Planned | B3: Design | C3: Research Relevance
A4: Unplanned | B4: Meeting | C4: Research Methodology
A5: Blocked | B5: Programming | C5: Research Application
A6: In-Progress | B6: Research | C6: Product Usefulness
A7: Done | B7: Testing | C7: Product Quality
A8: Delayed | B8: Workshop | C8: Project Management - Process
A9: Cancelled | B9: Planning | C9: Project Management - Risk
B10: Evidencing | C10: Professionalism - Collaboration
B11: Debugging | C11: Professionalism - Ethics/Legal
B12: Lecture | C12: Professionalism - Communication
B13: Study | C13: Learning - Feedback
B14: Unplanned | C14: Learning - Implementation
B15: Distraction
B16: Break
